Workbook
Name Slicer_Duration_Period: #N/A
Name Slicer_freelancer_ID: #N/A
Name Slicer_freelancer_ID1: #N/A
Name Slicer_freelancer_ID2: #N/A
Name Slicer_is_active: #N/A
Name Slicer_is_active1: #N/A
Name Slicer_no_of_projects: #N/A
Name Slicer_primary_skill: #N/A
Name Slicer_rating: #N/A

Sheet global_freelancer_raw
A1: freelancer_ID | B1: name | C1: gender | D1: age | E1: Index and Match Mode gender | F1: country | G1: language | H1: primary_skill | I1: years_of_experience | J1: hourly_rate (USD) | K1: rating | L1: is_active | M1: client_satisfaction | N1: Notes | O1: Status | P1: no of projects | Q1: duration_months | R1: Duration Period | S1: Client satisfaction analysis
A2: FL250001 | B2: Ms. Nicole Kidd | C2: Female | D2: 52 | F2: Italy | G2: Italian | H2: Blockchain Development | I2: 11 | J2: 100 | K2: 2.5125695 | L2: FALSE | M2: 0.79 | N2: Reviewed | O2: On Hold | P2: 13 | Q2: 6 | R2: =IF(global_freelancer_raw!$Q2 < 7, "Short Duration", IF(global_freelancer_raw!$Q2 <= 12, "Medium Duration", "Long Duration")) -> Short Duration | S2: =IF(global_freelancer_raw!$M2 <= 50%, "POOR", IF(global_freelancer_raw!$M2 <= 70%, "GOOD", "EXCELLENT")) -> EXCELLENT
A3: FL250002 | B3: Vanessa Garcia | C3: Female | D3: 52 | E3: {=INDEX(global_freelancer_raw!$C$2:$C$1001, MODE(MATCH(global_freelancer_raw!$C$2:$C$1001, global_freelancer_raw!$C$2:$C$1001, 0)))} -> Male | F3: Australia | G3: English | H3: Mobile Apps | I3: 34 | J3: 100 | K3: 3.3 | L3: TRUE | M3: 0.84 | N3: Reviewed | O3: Completed | P3: 10 | Q3: 7 | R3: =IF(global_freelancer_raw!$Q3 < 7, "Short Duration", IF(global_freelancer_raw!$Q3 <= 12, "Medium Duration", "Long Duration")) -> Medium Duration | S3: =IF(global_freelancer_raw!$M3 <= 50%, "POOR", IF(global_freelancer_raw!$M3 <= 70%, "GOOD", "EXCELLENT")) -> EXCELLENT
A4: FL250003 | B4: Juan Nelson | C4: Male | D4: 53 | E4: {=INDEX(global_freelancer_raw!$C$2:$C$1001, MODE(MATCH(global_freelancer_raw!$C$2:$C$1001, global_freelancer_raw!$C$2:$C$1001, 0)))} -> Male | F4: Germany | G4: Germany | H4: Graphic Design | I4: 31 | J4: 50 | K4: 0 | L4: FALSE | M4: 0.71 | N4: Reviewed | O4: Active | P4: 16 | Q4: 16 | R4: =IF(global_freelancer_raw!$Q4 < 7, "Short Duration", IF(global_freelancer_raw!$Q4 <= 12, "Medium Duration", "Long Duration")) -> Long Duration | S4: =IF(global_freelancer_raw!$M4 <= 50%, "POOR", IF(global_freelancer_raw!$M4 <= 70%, "GOOD", "EXCELLENT")) -> EXCELLENT
A5: FL250004 | B5: Amanda Spencer | C5: Female | D5: 38 | E5: {=INDEX(global_freelancer_raw!$C$2:$C$1001, MODE(MATCH(global_freelancer_raw!$C$2:$C$1001, global_freelancer_raw!$C$2:$C$1001, 0)))} -> Male | F5: Australia | G5: English | H5: Web Development | I5: 4 | J5: 40 | K5: 1.5 | L5: FALSE | M5: 0.9 | N5: Reviewed | O5: Completed | P5: 5 | Q5: 1 | R5: =IF(global_freelancer_raw!$Q5 < 7, "Short Duration", IF(global_freelancer_raw!$Q5 <= 12, "Medium Duration", "Long Duration")) -> Short Duration | S5: =IF(global_freelancer_raw!$M5 <= 50%, "POOR", IF(global_freelancer_raw!$M5 <= 70%, "GOOD", "EXCELLENT")) -> EXCELLENT
A6: FL250005 | B6: Lynn Curtis DDS | C6: Female | D6: 53 | E6: {=INDEX(global_freelancer_raw!$C$2:$C$1001, MODE(MATCH(global_freelancer_raw!$C$2:$C$1001, global_freelancer_raw!$C$2:$C$1001, 0)))} -> Male | F6: Germany | G6: Germany | I6: 27 | J6: 30 | K6: 4.8 | L6: FALSE | M6: 0.83 | N6: Reviewed | O6: On Hold | P6: 13 | Q6: 3 | R6: =IF(global_freelancer_raw!$Q6 < 7, "Short Duration", IF(global_freelancer_raw!$Q6 <= 12, "Medium Duration", "Long Duration")) -> Short Duration | S6: =IF(global_freelancer_raw!$M6 <= 50%, "POOR", IF(global_freelancer_raw!$M6 <= 70%, "GOOD", "EXCELLENT")) -> EXCELLENT
A7: FL250006 | B7: Lisa Johnson | C7: Female | D7: 59 | E7: {=INDEX(global_freelancer_raw!$C$2:$C$1001, MODE(MATCH(global_freelancer_raw!$C$2:$C$1001, global_freelancer_raw!$C$2:$C$1001, 0)))} -> Male | F7: Netherlands | G7: Dutch | H7: AI | I7: 14 | J7: 30 | K7: 2.4 | L7: FALSE | M7: 0.79 | N7: Urgent | O7: Active | P7: 8 | Q7: 3 | R7: =IF(global_freelancer_raw!$Q7 < 7, "Short Duration", IF(global_freelancer_raw!$Q7 <= 12, "Medium Duration", "Long Duration")) -> Short Duration | S7: =IF(global_freelancer_raw!$M7 <= 50%, "POOR", IF(global_freelancer_raw!$M7 <= 70%, "GOOD", "EXCELLENT")) -> EXCELLENT
A8: FL250007 | B8: Eric Myers | C8: Male | D8: 52 | E8: {=INDEX(global_freelancer_raw!$C$2:$C$1001, MODE(MATCH(global_freelancer_raw!$C$2:$C$1001, global_freelancer_raw!$C$2:$C$1001, 0)))} -> Male | F8: Indonesia | G8: Indonesian | H8: Data Analysis | I8: 10 | J8: 75 | K8: 3.1 | L8: FALSE | M8: 0.94 | N8: Reviewed | O8: On Hold | P8: 10 | Q8: 3 | R8: =IF(global_freelancer_raw!$Q8 < 7, "Short Duration", IF(global_freelancer_raw!$Q8 <= 12, "Medium Duration", "Long Duration")) -> Short Duration | S8: =IF(global_freelancer_raw!$M8 <= 50%, "POOR", IF(global_freelancer_raw!$M8 <= 70%, "GOOD", "EXCELLENT")) -> EXCELLENT
A9: FL250008 | B9: Ricky Graham | C9: Male | D9: 43 | E9: {=INDEX(global_freelancer_raw!$C$2:$C$1001, MODE(MATCH(global_freelancer_raw!$C$2:$C$1001, global_freelancer_raw!$C$2:$C$1001, 0)))} -> Male | F9: Italy | G9: Italian | H9: Blockchain Development | I9: 14 | J9: 40 | K9: 4.6 | L9: FALSE | M9: 0.94 | N9: Urgent | O9: On Hold | P9: 7 | Q9: 10 | R9: =IF(global_freelancer_raw!$Q9 < 7, "Short Duration", IF(global_freelancer_raw!$Q9 <= 12, "Medium Duration", "Long Duration")) -> Medium Duration | S9: =IF(global_freelancer_raw!$M9 <= 50%, "POOR", IF(global_freelancer_raw!$M9 <= 70%, "GOOD", "EXCELLENT")) -> EXCELLENT
A10: FL250009 | B10: Sean Martin | C10: Male | D10: 26 | E10: {=INDEX(global_freelancer_raw!$C$2:$C$1001, MODE(MATCH(global_freelancer_raw!$C$2:$C$1001, global_freelancer_raw!$C$2:$C$1001, 0)))} -> Male | F10: US | G10: English | H10: Blockchain Development | I10: 4 | J10: 52.461369 | K10: 4 | L10: TRUE | M10: 0.76 | N10: Reviewed | O10: Inactive | P10: 2 | Q10: 4 | R10: =IF(global_freelancer_raw!$Q10 < 7, "Short Duration", IF(global_freelancer_raw!$Q10 <= 12, "Medium Duration", "Long Duration")) -> Short Duration | S10: =IF(global_freelancer_raw!$M10 <= 50%, "POOR", IF(global_freelancer_raw!$M10 <= 70%, "GOOD", "EXCELLENT")) -> EXCELLENT
A11: FL250010 | B11: Matthew Lloyd | C11: Male | D11: 52 | E11: {=INDEX(global_freelancer_raw!$C$2:$C$1001, MODE(MATCH(global_freelancer_raw!$C$2:$C$1001, global_freelancer_raw!$C$2:$C$1001, 0)))} -> Male | F11: Turkey | G11: Turkish | H11: AI | I11: 22 | J11: 50 | K11: 2.5125695 | L11: TRUE | M11: 0.79 | N11: Pending | O11: Active | P11: 16 | Q11: 5 | R11: =IF(global_freelancer_raw!$Q11 < 7, "Short Duration", IF(global_freelancer_raw!$Q11 <= 12, "Medium Duration", "Long Duration")) -> Short Duration | S11: =IF(global_freelancer_raw!$M11 <= 50%, "POOR", IF(global_freelancer_raw!$M11 <= 70%, "GOOD", "EXCELLENT")) -> EXCELLENT
A12: FL250011 | B12: Gavin Randall | C12: Male | D12: 40 | E12: {=INDEX(global_freelancer_raw!$C$2:$C$1001, MODE(MATCH(global_freelancer_raw!$C$2:$C$1001, global_freelancer_raw!$C$2:$C$1001, 0)))} -> Male | F12: UK | G12: English | H12: Data Analysis | I12: 17 | J12: 40 | K12: 3.6 | L12: TRUE | M12: 0.77 | N12: Follow-up | O12: Inactive | P12: 20 | Q12: 5 | R12: =IF(global_freelancer_raw!$Q12 < 7, "Short Duration", IF(global_freelancer_raw!$Q12 <= 12, "Medium Duration", "Long Duration")) -> Short Duration | S12: =IF(global_freelancer_raw!$M12 <= 50%, "POOR", IF(global_freelancer_raw!$M12 <= 70%, "GOOD", "EXCELLENT")) -> EXCELLENT
A13: FL250012 | B13: Michelle Curtis | C13: Female | D13: 55 | E13: {=INDEX(global_freelancer_raw!$C$2:$C$1001, MODE(MATCH(global_freelancer_raw!$C$2:$C$1001, global_freelancer_raw!$C$2:$C$1001, 0)))} -> Male | F13: Argentina | G13: Spanish | H13: UI/UX Design | I13: 15 | J13: 52.461369 | K13: 2.5125695 | L13: TRUE | M13: 0.86 | N13: Urgent | O13: Active | P13: 13 | Q13: 4 | R13: =IF(global_freelancer_raw!$Q13 < 7, "Short Duration", IF(global_freelancer_raw!$Q13 <= 12, "Medium Duration", "Long Duration")) -> Short Duration | S13: =IF(global_freelancer_raw!$M13 <= 50%, "POOR", IF(global_freelancer_raw!$M13 <= 70%, "GOOD", "EXCELLENT")) -> EXCELLENT
A14: FL250013 | B14: Alice Schneider | C14: Female | D14: 57 | E14: {=INDEX(global_freelancer_raw!$C$2:$C$1001, MODE(MATCH(global_freelancer_raw!$C$2:$C$1001, global_freelancer_raw!$C$2:$C$1001, 0)))} -> Male | F14: UK | G14: English | H14: Cybersecurity | I14: 18 | J14: 52.461369 | K14: 2 | L14: FALSE | M14: 0.86 | N14: Reviewed | O14: On Hold | P14: 16 | Q14: 15 | R14: =IF(global_freelancer_raw!$Q14 < 7, "Short Duration", IF(global_freelancer_raw!$Q14 <= 12, "Medium Duration", "Long Duration")) -> Long Duration | S14: =IF(global_freelancer_raw!$M14 <= 50%, "POOR", IF(global_freelancer_raw!$M14 <= 70%, "GOOD", "EXCELLENT")) -> EXCELLENT
A15: FL250014 | B15: Phillip Shelton | C15: Male | D15: 38 | E15: {=INDEX(global_freelancer_raw!$C$2:$C$1001, MODE(MATCH(global_freelancer_raw!$C$2:$C$1001, global_freelancer_raw!$C$2:$C$1001, 0)))} -> Male | G15: Spanish | H15: Graphic Design | I15: 20 | J15: 75 | K15: 2.9 | L15: TRUE | M15: 0.93 | N15: Pending | O15: On Hold | P15: 17 | Q15: 12 | R15: =IF(global_freelancer_raw!$Q15 < 7, "Short Duration", IF(global_freelancer_raw!$Q15 <= 12, "Medium Duration", "Long Duration")) -> Medium Duration | S15: =IF(global_freelancer_raw!$M15 <= 50%, "POOR", IF(global_freelancer_raw!$M15 <= 70%, "GOOD", "EXCELLENT")) -> EXCELLENT
A16: FL250015 | B16: Edward Ferguson | C16: Male | D16: 50 | E16: {=INDEX(global_freelancer_raw!$C$2:$C$1001, MODE(MATCH(global_freelancer_raw!$C$2:$C$1001, global_freelancer_raw!$C$2:$C$1001, 0)))} -> Male | F16: Germany | G16: Germany | H16: Data Analysis | I16: 22 | J16: 75 | K16: 3.7 | L16: TRUE | M16: 0.7 | N16: Follow-up | O16: Completed | P16: 14 | Q16: 6 | R16: =IF(global_freelancer_raw!$Q16 < 7, "Short Duration", IF(global_freelancer_raw!$Q16 <= 12, "Medium Duration", "Long Duration")) -> Short Duration | S16: =IF(global_freelancer_raw!$M16 <= 50%, "POOR", IF(global_freelancer_raw!$M16 <= 70%, "GOOD", "EXCELLENT")) -> GOOD
A17: FL250016 | B17: Wyatt Stout | C17: Male | D17: 42 | E17: {=INDEX(global_freelancer_raw!$C$2:$C$1001, MODE(MATCH(global_freelancer_raw!$C$2:$C$1001, global_freelancer_raw!$C$2:$C$1001, 0)))} -> Male | F17: Japan | G17: Japanese | I17: 0 | J17: 30 | K17: 1.2 | L17: FALSE | M17: 0.69 | N17: Urgent | O17: Active | P17: 5 | Q17: 2 | R17: =IF(global_freelancer_raw!$Q17 < 7, "Short Duration", IF(global_freelancer_raw!$Q17 <= 12, "Medium Duration", "Long Duration")) -> Short Duration | S17: =IF(global_freelancer_raw!$M17 <= 50%, "POOR", IF(global_freelancer_raw!$M17 <= 70%, "GOOD", "EXCELLENT")) -> GOOD
A18: FL250017 | B18: Laura Johnson | C18: Female | D18: 39 | E18: {=INDEX(global_freelancer_raw!$C$2:$C$1001, MODE(MATCH(global_freelancer_raw!$C$2:$C$1001, global_freelancer_raw!$C$2:$C$1001, 0)))} -> Male | F18: Australia | G18: English | H18: DevOps | I18: 13 | J18: 30 | K18: 2.5 | L18: FALSE | M18: 0.6 | N18: Follow-up | O18: Inactive | P18: 7 | Q18: 1 | R18: =IF(global_freelancer_raw!$Q18 < 7, "Short Duration", IF(global_freelancer_raw!$Q18 <= 12, "Medium Duration", "Long Duration")) -> Short Duration | S18: =IF(global_freelancer_raw!$M18 <= 50%, "POOR", IF(global_freelancer_raw!$M18 <= 70%, "GOOD", "EXCELLENT")) -> GOOD
A19: FL250018 | B19: Scott Burns | C19: Male | D19: 56 | E19: {=INDEX(global_freelancer_raw!$C$2:$C$1001, MODE(MATCH(global_freelancer_raw!$C$2:$C$1001, global_freelancer_raw!$C$2:$C$1001, 0)))} -> Male | F19: India | G19: Hindi | H19: Blockchain Development | I19: 0 | J19: 52.461369 | K19: 2.5125695 | L19: Unknown | M19: 0.87 | N19: Pending | O19: Completed | P19: 1 | Q19: 2 | R19: =IF(global_freelancer_raw!$Q19 < 7, "Short Duration", IF(global_freelancer_raw!$Q19 <= 12, "Medium Duration", "Long Duration")) -> Short Duration | S19: =IF(global_freelancer_raw!$M19 <= 50%, "POOR", IF(global_freelancer_raw!$M19 <= 70%, "GOOD", "EXCELLENT")) -> EXCELLENT
A20: FL250019 | B20: Tyler Aguirre | C20: Male | D20: 56 | E20: {=INDEX(global_freelancer_raw!$C$2:$C$1001, MODE(MATCH(global_freelancer_raw!$C$2:$C$1001, global_freelancer_raw!$C$2:$C$1001, 0)))} -> Male | F20: US | G20: English | H20: UI/UX Design | I20: 31 | J20: 50 | K20: 1.1 | L20: FALSE | M20: 0.75 | N20: Urgent | O20: Completed | P20: 13 | Q20: 3 | R20: =IF(global_freelancer_raw!$Q20 < 7, "Short Duration", IF(global_freelancer_raw!$Q20 <= 12, "Medium Duration", "Long Duration")) -> Short Duration | S20: =IF(global_freelancer_raw!$M20 <= 50%, "POOR", IF(global_freelancer_raw!$M20 <= 70%, "GOOD", "EXCELLENT")) -> EXCELLENT
A21: FL250020 | B21: Matthew Lawson | C21: Male | D21: 57 | E21: {=INDEX(global_freelancer_raw!$C$2:$C$1001, MODE(MATCH(global_freelancer_raw!$C$2:$C$1001, global_freelancer_raw!$C$2:$C$1001, 0)))} -> Male | F21: Italy | G21: Italian | H21: Web Development | I21: 3 | J21: 100 | K21: 1.8 | L21: TRUE | M21: 0.68 | N21: Follow-up | O21: Completed | P21: 1 | Q21: 1 | R21: =IF(global_freelancer_raw!$Q21 < 7, "Short Duration", IF(global_freelancer_raw!$Q21 <= 12, "Medium Duration", "Long Duration")) -> Short Duration | S21: =IF(global_freelancer_raw!$M21 <= 50%, "POOR", IF(global_freelancer_raw!$M21 <= 70%, "GOOD", "EXCELLENT")) -> GOOD
A22: FL250021 | B22: James Cherry | C22: Male | E22: {=INDEX(global_freelancer_raw!$C$2:$C$1001, MODE(MATCH(global_freelancer_raw!$C$2:$C$1001, global_freelancer_raw!$C$2:$C$1001, 0)))} -> Male | F22: Indonesia | G22: Indonesian | H22: AI | I22: 9 | J22: 50 | K22: 1.8 | L22: FALSE | M22: 0.65 | N22: Reviewed | O22: Inactive | P22: 15 | Q22: 6 | R22: =IF(global_freelancer_raw!$Q22 < 7, "Short Duration", IF(global_freelancer_raw!$Q22 <= 12, "Medium Duration", "Long Duration")) -> Short Duration | S22: =IF(global_freelancer_raw!$M22 <= 50%, "POOR", IF(global_freelancer_raw!$M22 <= 70%, "GOOD", "EXCELLENT")) -> GOOD
A23: FL250022 | B23: Samuel Sanford | C23: Male | D23: 51 | E23: {=INDEX(global_freelancer_raw!$C$2:$C$1001, MODE(MATCH(global_freelancer_raw!$C$2:$C$1001, global_freelancer_raw!$C$2:$C$1001, 0)))} -> Male | F23: Japan | G23: Japanese | H23: DevOps | I23: 0 | J23: 52.461369 | K23: 2.4 | L23: FALSE | M23: 0.69 | N23: Urgent | O23: Completed | P23: 3 | Q23: 5 | R23: =IF(global_freelancer_raw!$Q23 < 7, "Short Duration", IF(global_freelancer_raw!$Q23 <= 12, "Medium Duration", "Long Duration")) -> Short Duration | S23: =IF(global_freelancer_raw!$M23 <= 50%, "POOR", IF(global_freelancer_raw!$M23 <= 70%, "GOOD", "EXCELLENT")) -> GOOD
A24: FL250023 | B24: Cesar Greene | C24: Male | D24: 51 | E24: {=INDEX(global_freelancer_raw!$C$2:$C$1001, MODE(MATCH(global_freelancer_raw!$C$2:$C$1001, global_freelancer_raw!$C$2:$C$1001, 0)))} -> Male | F24: Brazil | G24: Portuguese | H24: Cybersecurity | I24: 21 | J24: 30 | K24: 4.7 | L24: FALSE | M24: 0.79 | N24: Follow-up | O24: Inactive | P24: 14 | Q24: 2 | R24: =IF(global_freelancer_raw!$Q24 < 7, "Short Duration", IF(global_freelancer_raw!$Q24 <= 12, "Medium Duration", "Long Duration")) -> Short Duration | S24: =IF(global_freelancer_raw!$M24 <= 50%, "POOR", IF(global_freelancer_raw!$M24 <= 70%, "GOOD", "EXCELLENT")) -> EXCELLENT
A25: FL250024 | B25: Melanie Carter | C25: Female | D25: 51 | E25: {=INDEX(global_freelancer_raw!$C$2:$C$1001, MODE(MATCH(global_freelancer_raw!$C$2:$C$1001, global_freelancer_raw!$C$2:$C$1001, 0)))} -> Male | F25: South Korea | G25: Korean | H25: Machine Learning | I25: 15 | J25: 50 | K25: 1.3 | L25: TRUE | M25: 1 | N25: Pending | O25: Completed | P25: 9 | Q25: 3 | R25: =IF(global_freelancer_raw!$Q25 < 7, "Short Duration", IF(global_freelancer_raw!$Q25 <= 12, "Medium Duration", "Long Duration")) -> Short Duration | S25: =IF(global_freelancer_raw!$M25 <= 50%, "POOR", IF(global_freelancer_raw!$M25 <= 70%, "GOOD", "EXCELLENT")) -> EXCELLENT
A26: FL250025 | B26: Jennifer Martin | C26: Female | D26: 54 | E26: {=INDEX(global_freelancer_raw!$C$2:$C$1001, MODE(MATCH(global_freelancer_raw!$C$2:$C$1001, global_freelancer_raw!$C$2:$C$1001, 0)))} -> Male | F26: Indonesia | G26: Indonesian | H26: Machine Learning | I26: 13 | J26: 75 | K26: 2.9 | L26: Unknown | M26: 0.92 | N26: Pending | O26: Inactive | P26: 15 | Q26: 3 | R26: =IF(global_freelancer_raw!$Q26 < 7, "Short Duration", IF(global_freelancer_raw!$Q26 <= 12, "Medium Duration", "Long Duration")) -> Short Duration | S26: =IF(global_freelancer_raw!$M26 <= 50%, "POOR", IF(global_freelancer_raw!$M26 <= 70%, "GOOD", "EXCELLENT")) -> EXCELLENT
A27: FL250026 | B27: Anna Mccann | C27: Female | D27: 22 | E27: {=INDEX(global_freelancer_raw!$C$2:$C$1001, MODE(MATCH(global_freelancer_raw!$C$2:$C$1001, global_freelancer_raw!$C$2:$C$1001, 0)))} -> Male | F27: South Korea | G27: Korean | H27: DevOps | I27: 0 | J27: 30 | K27: 1.2 | L27: TRUE | M27: 0.7 | N27: Urgent | O27: On Hold | P27: 5 | Q27: 2 | R27: =IF(global_freelancer_raw!$Q27 < 7, "Short Duration", IF(global_freelancer_raw!$Q27 <= 12, "Medium Duration", "Long Duration")) -> Short Duration | S27: =IF(global_freelancer_raw!$M27 <= 50%, "POOR", IF(global_freelancer_raw!$M27 <= 70%, "GOOD", "EXCELLENT")) -> GOOD
A28: FL250027 | B28: Marissa Bass | C28: Female | D28: 34 | E28: {=INDEX(global_freelancer_raw!$C$2:$C$1001, MODE(MATCH(global_freelancer_raw!$C$2:$C$1001, global_freelancer_raw!$C$2:$C$1001, 0)))} -> Male | F28: Japan | G28: Japanese | H28: Blockchain Development | I28: 8 | J28: 20 | K28: 0 | L28: TRUE | M28: 0.89 | N28: Follow-up | O28: On Hold | P28: 6 | Q28: 1 | R28: =IF(global_freelancer_raw!$Q28 < 7, "Short Duration", IF(global_freelancer_raw!$Q28 <= 12, "Medium Duration", "Long Duration")) -> Short Duration | S28: =IF(global_freelancer_raw!$M28 <= 50%, "POOR", IF(global_freelancer_raw!$M28 <= 70%, "GOOD", "EXCELLENT")) -> EXCELLENT
A29: FL250028 | B29: Alexis Day | C29: Female | D29: 36 | E29: {=INDEX(global_freelancer_raw!$C$2:$C$1001, MODE(MATCH(global_freelancer_raw!$C$2:$C$1001, global_freelancer_raw!$C$2:$C$1001, 0)))} -> Male | F29: Russia | G29: Russian | H29: Graphic Design | I29: 11 | J29: 52.461369 | K29: 1.8 | L29: TRUE | M29: 0.86 | N29: Urgent | O29: On Hold | P29: 12 | Q29: 4 | R29: =IF(global_freelancer_raw!$Q29 < 7, "Short Duration", IF(global_freelancer_raw!$Q29 <= 12, "Medium Duration", "Long Duration")) -> Short Duration | S29: =IF(global_freelancer_raw!$M29 <= 50%, "POOR", IF(global_freelancer_raw!$M29 <= 70%, "GOOD", "EXCELLENT")) -> EXCELLENT
A30: FL250029 | B30: Megan Jones | C30: Female | D30: 47 | E30: {=INDEX(global_freelancer_raw!$C$2:$C$1001, MODE(MATCH(global_freelancer_raw!$C$2:$C$1001, global_freelancer_raw!$C$2:$C$1001, 0)))} -> Male | F30: Canada | G30: English | H30: AI | I30: 22 | J30: 30 | K30: 1.3 | L30: FALSE | M30: 0.62 | N30: Urgent | O30: On Hold | P30: 14 | Q30: 2 | R30: =IF(global_freelancer_raw!$Q30 < 7, "Short Duration", IF(global_freelancer_raw!$Q30 <= 12, "Medium Duration", "Long Duration")) -> Short Duration | S30: =IF(global_freelancer_raw!$M30 <= 50%, "POOR", IF(global_freelancer_raw!$M30 <= 70%, "GOOD", "EXCELLENT")) -> GOOD
A31: FL250030 | B31: Lori Smith | C31: Female | D31: 41 | E31: {=INDEX(global_freelancer_raw!$C$2:$C$1001, MODE(MATCH(global_freelancer_raw!$C$2:$C$1001, global_freelancer_raw!$C$2:$C$1001, 0)))} -> Male | F31: Netherlands | G31: Dutch | H31: Data Analysis | I31: 14 | J31: 75 | K31: 1.2 | L31: FALSE | M31: 0.79 | N31: Follow-up | O31: On Hold | P31: 6 | Q31: 5 | R31: =IF(global_freelancer_raw!$Q31 < 7, "Short Duration", IF(global_freelancer_raw!$Q31 <= 12, "Medium Duration", "Long Duration")) -> Short Duration | S31: =IF(global_freelancer_raw!$M31 <= 50%, "POOR", IF(global_freelancer_raw!$M31 <= 70%, "GOOD", "EXCELLENT")) -> EXCELLENT
A32: FL250031 | B32: Eric Carpenter | C32: Male | D32: 22 | E32: {=INDEX(global_freelancer_raw!$C$2:$C$1001, MODE(MATCH(global_freelancer_raw!$C$2:$C$1001, global_freelancer_raw!$C$2:$C$1001, 0)))} -> Male | F32: Netherlands | G32: Dutch | H32: DevOps | I32: 4 | J32: 52.461369 | K32: 1 | L32: TRUE | M32: 0.79 | N32: Follow-up | O32: Completed | P32: 3 | Q32: 1 | R32: =IF(global_freelancer_raw!$Q32 < 7, "Short Duration", IF(global_freelancer_raw!$Q32 <= 12, "Medium Duration", "Long Duration")) -> Short Duration | S32: =IF(global_freelancer_raw!$M32 <= 50%, "POOR", IF(global_freelancer_raw!$M32 <= 70%, "GOOD", "EXCELLENT")) -> EXCELLENT
A33: FL250032 | B33: Timothy Daniels | C33: Male | D33: 38 | E33: {=INDEX(global_freelancer_raw!$C$2:$C$1001, MODE(MATCH(global_freelancer_raw!$C$2:$C$1001, global_freelancer_raw!$C$2:$C$1001, 0)))} -> Male | F33: France | G33: French | H33: Machine Learning | I33: 19 | J33: 100 | K33: 4.2 | L33: FALSE | M33: 0.68 | N33: Reviewed | O33: Completed | P33: 10 | Q33: 10 | R33: =IF(global_freelancer_raw!$Q33 < 7, "Short Duration", IF(global_freelancer_raw!$Q33 <= 12, "Medium Duration", "Long Duration")) -> Medium Duration | S33: =IF(global_freelancer_raw!$M33 <= 50%, "POOR", IF(global_freelancer_raw!$M33 <= 70%, "GOOD", "EXCELLENT")) -> GOOD
A34: FL250033 | B34: Robert Nelson | C34: Male | D34: 46 | E34: {=INDEX(global_freelancer_raw!$C$2:$C$1001, MODE(MATCH(global_freelancer_raw!$C$2:$C$1001, global_freelancer_raw!$C$2:$C$1001, 0)))} -> Male | F34: Egypt | G34: Arabic | H34: AI | I34: 9 | J34: 20 | K34: 1.4 | L34: TRUE | M34: 0.76 | N34: Follow-up | O34: Completed | P34: 13 | Q34: 6 | R34: =IF(global_freelancer_raw!$Q34 < 7, "Short Duration", IF(global_freelancer_raw!$Q34 <= 12, "Medium Duration", "Long Duration")) -> Short Duration | S34: =IF(global_freelancer_raw!$M34 <= 50%, "POOR", IF(global_freelancer_raw!$M34 <= 70%, "GOOD", "EXCELLENT")) -> EXCELLENT
A35: FL250034 | B35: Michael Anderson | C35: Male | E35: {=INDEX(global_freelancer_raw!$C$2:$C$1001, MODE(MATCH(global_freelancer_raw!$C$2:$C$1001, global_freelancer_raw!$C$2:$C$1001, 0)))} -> Male | F35: South Korea | G35: Korean | H35: AI | I35: 9 | J35: 40 | K35: 2.4 | L35: TRUE | M35: 0.82 | N35: Pending | O35: Inactive | P35: 15 | Q35: 3 | R35: =IF(global_freelancer_raw!$Q35 < 7, "Short Duration", IF(global_freelancer_raw!$Q35 <= 12, "Medium Duration", "Long Duration")) -> Short Duration | S35: =IF(global_freelancer_raw!$M35 <= 50%, "POOR", IF(global_freelancer_raw!$M35 <= 70%, "GOOD", "EXCELLENT")) -> EXCELLENT
A36: FL250035 | B36: Jessica Snyder | C36: Female | D36: 54 | E36: {=INDEX(global_freelancer_raw!$C$2:$C$1001, MODE(MATCH(global_freelancer_raw!$C$2:$C$1001, global_freelancer_raw!$C$2:$C$1001, 0)))} -> Male | F36: US | G36: English | H36: Web Development | I36: 32 | J36: 75 | K36: 1 | L36: TRUE | M36: 0.81 | N36: Urgent | O36: Inactive | P36: 18 | Q36: 10 | R36: =IF(global_freelancer_raw!$Q36 < 7, "Short Duration", IF(global_freelancer_raw!$Q36 <= 12, "Medium Duration", "Long Duration")) -> Medium Duration | S36: =IF(global_freelancer_raw!$M36 <= 50%, "POOR", IF(global_freelancer_raw!$M36 <= 70%, "GOOD", "EXCELLENT")) -> EXCELLENT
A37: FL250036 | B37: Emily Daniels | C37: Female | D37: 52 | E37: {=INDEX(global_freelancer_raw!$C$2:$C$1001, MODE(MATCH(global_freelancer_raw!$C$2:$C$1001, global_freelancer_raw!$C$2:$C$1001, 0)))} -> Male | F37: South Korea | G37: Korean | I37: 28 | J37: 20 | K37: 2.5125695 | L37: FALSE | M37: 0.79 | N37: Urgent | O37: Inactive | P37: 18 | Q37: 2 | R37: =IF(global_freelancer_raw!$Q37 < 7, "Short Duration", IF(global_freelancer_raw!$Q37 <= 12, "Medium Duration", "Long Duration")) -> Short Duration | S37: =IF(global_freelancer_raw!$M37 <= 50%, "POOR", IF(global_freelancer_raw!$M37 <= 70%, "GOOD", "EXCELLENT")) -> EXCELLENT
A38: FL250037 | B38: Jamie Ramirez | C38: Female | D38: 42 | E38: {=INDEX(global_freelancer_raw!$C$2:$C$1001, MODE(MATCH(global_freelancer_raw!$C$2:$C$1001, global_freelancer_raw!$C$2:$C$1001, 0)))} -> Male | F38: Japan | G38: Japanese | H38: Mobile Apps | I38: 6 | J38: 40 | K38: 2.5125695 | L38: FALSE | M38: 0.63 | N38: Pending | O38: Inactive | P38: 15 | Q38: 6 | R38: =IF(global_freelancer_raw!$Q38 < 7, "Short Duration", IF(global_freelancer_raw!$Q38 <= 12, "Medium Duration", "Long Duration")) -> Short Duration | S38: =IF(global_freelancer_raw!$M38 <= 50%, "POOR", IF(global_freelancer_raw!$M38 <= 70%, "GOOD", "EXCELLENT")) -> GOOD
A39: FL250038 | B39: Amy Harrison | C39: Female | D39: 29 | E39: {=INDEX(global_freelancer_raw!$C$2:$C$1001, MODE(MATCH(global_freelancer_raw!$C$2:$C$1001, global_freelancer_raw!$C$2:$C$1001, 0)))} -> Male | F39: Netherlands | G39: Dutch | H39: Graphic Design | I39: 10 | J39: 40 | K39: 2.2 | L39: FALSE | M39: 0.67 | N39: Follow-up | O39: On Hold | P39: 10 | Q39: 9 | R39: =IF(global_freelancer_raw!$Q39 < 7, "Short Duration", IF(global_freelancer_raw!$Q39 <= 12, "Medium Duration", "Long Duration")) -> Medium Duration | S39: =IF(global_freelancer_raw!$M39 <= 50%, "POOR", IF(global_freelancer_raw!$M39 <= 70%, "GOOD", "EXCELLENT")) -> GOOD
A40: FL250039 | B40: Melinda White | C40: Female | D40: 42 | E40: {=INDEX(global_freelancer_raw!$C$2:$C$1001, MODE(MATCH(global_freelancer_raw!$C$2:$C$1001, global_freelancer_raw!$C$2:$C$1001, 0)))} -> Male | F40: South Africa | G40: Afrikaans | H40: Mobile Apps | I40: 23 | J40: 50 | K40: 3.2 | L40: TRUE | M40: 0.79 | N40: Pending | O40: On Hold | P40: 13 | Q40: 3 | R40: =IF(global_freelancer_raw!$Q40 < 7, "Short Duration", IF(global_freelancer_raw!$Q40 <= 12, "Medium Duration", "Long Duration")) -> Short Duration | S40: =IF(global_freelancer_raw!$M40 <= 50%, "POOR", IF(global_freelancer_raw!$M40 <= 70%, "GOOD", "EXCELLENT")) -> EXCELLENT
...

Sheet global_freelancer-quick ana
A1: freelancer_ID | B1: name | C1: gender | D1: age | E1: Index and Match Mode gender | F1: country | G1: language | H1: primary_skill | I1: years_of_experience | J1: hourly_rate (USD) | K1: rating | L1: is_active | M1: client_satisfaction | N1: Notes | O1: Status | P1: no of projects | Q1: duration_months | R1: Duration Period | S1: Client satisfaction analysis | T1: Sum
A2: FL250001 | B2: Ms. Nicole Kidd | C2: Female | D2: 52 | F2: Italy | G2: Italian | H2: Blockchain Development | I2: 11 | J2: 100 | K2: 2.5125695 | L2: FALSE | M2: 0.79 | N2: Reviewed | O2: On Hold | P2: 13 | Q2: 6 | R2: =IF('global_freelancer-quick ana'!$Q2 < 7, "Short Duration", IF('global_freelancer-quick ana'!$Q2 <= 12, "Medium Duration", "Long Duration")) -> Short Duration | S2: =IF('global_freelancer-quick ana'!$M2 <= 50%, "POOR", IF('global_freelancer-quick ana'!$M2 <= 70%, "GOOD", "EXCELLENT")) -> EXCELLENT | T2: =SUM(B2:S2) -> 185.30257
A3: FL250002 | B3: Vanessa Garcia | C3: Female | D3: 52 | E3: {=INDEX('global_freelancer-quick ana'!$C$2:$C$1001, MODE(MATCH('global_freelancer-quick ana'!$C$2:$C$1001, 'global_freelancer-quick ana'!$C$2:$C$1001, 0)))} -> Male | F3: Australia | G3: English | H3: Mobile Apps | I3: 34 | J3: 100 | K3: 3.3 | L3: TRUE | M3: 0.84 | N3: Reviewed | O3: Completed | P3: 10 | Q3: 7 | R3: =IF('global_freelancer-quick ana'!$Q3 < 7, "Short Duration", IF('global_freelancer-quick ana'!$Q3 <= 12, "Medium Duration", "Long Duration")) -> Medium Duration | S3: =IF('global_freelancer-quick ana'!$M3 <= 50%, "POOR", IF('global_freelancer-quick ana'!$M3 <= 70%, "GOOD", "EXCELLENT")) -> EXCELLENT | T3: =SUM(B3:S3) -> 207.14
A4: FL250003 | B4: Juan Nelson | C4: Male | D4: 53 | E4: {=INDEX('global_freelancer-quick ana'!$C$2:$C$1001, MODE(MATCH('global_freelancer-quick ana'!$C$2:$C$1001, 'global_freelancer-quick ana'!$C$2:$C$1001, 0)))} -> Male | F4: Germany | G4: Germany | H4: Graphic Design | I4: 31 | J4: 50 | K4: 0 | L4: FALSE | M4: 0.71 | N4: Reviewed | O4: Active | P4: 16 | Q4: 16 | R4: =IF('global_freelancer-quick ana'!$Q4 < 7, "Short Duration", IF('global_freelancer-quick ana'!$Q4 <= 12, "Medium Duration", "Long Duration")) -> Long Duration | S4: =IF('global_freelancer-quick ana'!$M4 <= 50%, "POOR", IF('global_freelancer-quick ana'!$M4 <= 70%, "GOOD", "EXCELLENT")) -> EXCELLENT | T4: =SUM(B4:S4) -> 166.71
A5: FL250004 | B5: Amanda Spencer | C5: Female | D5: 38 | E5: {=INDEX('global_freelancer-quick ana'!$C$2:$C$1001, MODE(MATCH('global_freelancer-quick ana'!$C$2:$C$1001, 'global_freelancer-quick ana'!$C$2:$C$1001, 0)))} -> Male | F5: Australia | G5: English | H5: Web Development | I5: 4 | J5: 40 | K5: 1.5 | L5: FALSE | M5: 0.9 | N5: Reviewed | O5: Completed | P5: 5 | Q5: 1 | R5: =IF('global_freelancer-quick ana'!$Q5 < 7, "Short Duration", IF('global_freelancer-quick ana'!$Q5 <= 12, "Medium Duration", "Long Duration")) -> Short Duration | S5: =IF('global_freelancer-quick ana'!$M5 <= 50%, "POOR", IF('global_freelancer-quick ana'!$M5 <= 70%, "GOOD", "EXCELLENT")) -> EXCELLENT | T5: =SUM(B5:S5) -> 90.4
A6: FL250005 | B6: Lynn Curtis DDS | C6: Female | D6: 53 | E6: {=INDEX('global_freelancer-quick ana'!$C$2:$C$1001, MODE(MATCH('global_freelancer-quick ana'!$C$2:$C$1001, 'global_freelancer-quick ana'!$C$2:$C$1001, 0)))} -> Male | F6: Germany | G6: Germany | I6: 27 | J6: 30 | K6: 4.8 | L6: FALSE | M6: 0.83 | N6: Reviewed | O6: On Hold | P6: 13 | Q6: 3 | R6: =IF('global_freelancer-quick ana'!$Q6 < 7, "Short Duration", IF('global_freelancer-quick ana'!$Q6 <= 12, "Medium Duration", "Long Duration")) -> Short Duration | S6: =IF('global_freelancer-quick ana'!$M6 <= 50%, "POOR", IF('global_freelancer-quick ana'!$M6 <= 70%, "GOOD", "EXCELLENT")) -> EXCELLENT | T6: =SUM(B6:S6) -> 131.63
A7: FL250006 | B7: Lisa Johnson | C7: Female | D7: 59 | E7: {=INDEX('global_freelancer-quick ana'!$C$2:$C$1001, MODE(MATCH('global_freelancer-quick ana'!$C$2:$C$1001, 'global_freelancer-quick ana'!$C$2:$C$1001, 0)))} -> Male | F7: Netherlands | G7: Dutch | H7: AI | I7: 14 | J7: 30 | K7: 2.4 | L7: FALSE | M7: 0.79 | N7: Urgent | O7: Active | P7: 8 | Q7: 3 | R7: =IF('global_freelancer-quick ana'!$Q7 < 7, "Short Duration", IF('global_freelancer-quick ana'!$Q7 <= 12, "Medium Duration", "Long Duration")) -> Short Duration | S7: =IF('global_freelancer-quick ana'!$M7 <= 50%, "POOR", IF('global_freelancer-quick ana'!$M7 <= 70%, "GOOD", "EXCELLENT")) -> EXCELLENT | T7: =SUM(B7:S7) -> 117.19
A8: FL250007 | B8: Eric Myers | C8: Male | D8: 52 | E8: {=INDEX('global_freelancer-quick ana'!$C$2:$C$1001, MODE(MATCH('global_freelancer-quick ana'!$C$2:$C$1001, 'global_freelancer-quick ana'!$C$2:$C$1001, 0)))} -> Male | F8: Indonesia | G8: Indonesian | H8: Data Analysis | I8: 10 | J8: 75 | K8: 3.1 | L8: FALSE | M8: 0.94 | N8: Reviewed | O8: On Hold | P8: 10 | Q8: 3 | R8: =IF('global_freelancer-quick ana'!$Q8 < 7, "Short Duration", IF('global_freelancer-quick ana'!$Q8 <= 12, "Medium Duration", "Long Duration")) -> Short Duration | S8: =IF('global_freelancer-quick ana'!$M8 <= 50%, "POOR", IF('global_freelancer-quick ana'!$M8 <= 70%, "GOOD", "EXCELLENT")) -> EXCELLENT | T8: =SUM(B8:S8) -> 154.04
A9: FL250008 | B9: Ricky Graham | C9: Male | D9: 43 | E9: {=INDEX('global_freelancer-quick ana'!$C$2:$C$1001, MODE(MATCH('global_freelancer-quick ana'!$C$2:$C$1001, 'global_freelancer-quick ana'!$C$2:$C$1001, 0)))} -> Male | F9: Italy | G9: Italian | H9: Blockchain Development | I9: 14 | J9: 40 | K9: 4.6 | L9: FALSE | M9: 0.94 | N9: Urgent | O9: On Hold | P9: 7 | Q9: 10 | R9: =IF('global_freelancer-quick ana'!$Q9 < 7, "Short Duration", IF('global_freelancer-quick ana'!$Q9 <= 12, "Medium Duration", "Long Duration")) -> Medium Duration | S9: =IF('global_freelancer-quick ana'!$M9 <= 50%, "POOR", IF('global_freelancer-quick ana'!$M9 <= 70%, "GOOD", "EXCELLENT")) -> EXCELLENT | T9: =SUM(B9:S9) -> 119.54
A10: FL250009 | B10: Sean Martin | C10: Male | D10: 26 | E10: {=INDEX('global_freelancer-quick ana'!$C$2:$C$1001, MODE(MATCH('global_freelancer-quick ana'!$C$2:$C$1001, 'global_freelancer-quick ana'!$C$2:$C$1001, 0)))} -> Male | F10: US | G10: English | H10: Blockchain Development | I10: 4 | K10: 4 | L10: TRUE | M10: 0.76 | N10: Reviewed | O10: Inactive | P10: 2 | Q10: 4 | R10: =IF('global_freelancer-quick ana'!$Q10 < 7, "Short Duration", IF('global_freelancer-quick ana'!$Q10 <= 12, "Medium Duration", "Long Duration")) -> Short Duration | S10: =IF('global_freelancer-quick ana'!$M10 <= 50%, "POOR", IF('global_freelancer-quick ana'!$M10 <= 70%, "GOOD", "EXCELLENT")) -> EXCELLENT | T10: =SUM(B10:S10) -> 40.76
A11: FL250010 | B11: Matthew Lloyd | C11: Male | D11: 52 | E11: {=INDEX('global_freelancer-quick ana'!$C$2:$C$1001, MODE(MATCH('global_freelancer-quick ana'!$C$2:$C$1001, 'global_freelancer-quick ana'!$C$2:$C$1001, 0)))} -> Male | F11: Turkey | G11: Turkish | H11: AI | I11: 22 | J11: 50 | K11: 2.5125695 | L11: TRUE | M11: 0.79 | N11: Pending | O11: Active | P11: 16 | Q11: 5 | R11: =IF('global_freelancer-quick ana'!$Q11 < 7, "Short Duration", IF('global_freelancer-quick ana'!$Q11 <= 12, "Medium Duration", "Long Duration")) -> Short Duration | S11: =IF('global_freelancer-quick ana'!$M11 <= 50%, "POOR", IF('global_freelancer-quick ana'!$M11 <= 70%, "GOOD", "EXCELLENT")) -> EXCELLENT | T11: =SUM(B11:S11) -> 148.30257
A12: FL250011 | B12: Gavin Randall | C12: Male | D12: 40 | E12: {=INDEX('global_freelancer-quick ana'!$C$2:$C$1001, MODE(MATCH('global_freelancer-quick ana'!$C$2:$C$1001, 'global_freelancer-quick ana'!$C$2:$C$1001, 0)))} -> Male | F12: UK | G12: English | H12: Data Analysis | I12: 17 | J12: 40 | K12: 3.6 | L12: TRUE | M12: 0.77 | N12: Follow-up | O12: Inactive | P12: 20 | Q12: 5 | R12: =IF('global_freelancer-quick ana'!$Q12 < 7, "Short Duration", IF('global_freelancer-quick ana'!$Q12 <= 12, "Medium Duration", "Long Duration")) -> Short Duration | S12: =IF('global_freelancer-quick ana'!$M12 <= 50%, "POOR", IF('global_freelancer-quick ana'!$M12 <= 70%, "GOOD", "EXCELLENT")) -> EXCELLENT | T12: =SUM(B12:S12) -> 86.37
A13: FL250012 | B13: Michelle Curtis | C13: Female | D13: 55 | E13: {=INDEX('global_freelancer-quick ana'!$C$2:$C$1001, MODE(MATCH('global_freelancer-quick ana'!$C$2:$C$1001, 'global_freelancer-quick ana'!$C$2:$C$1001, 0)))} -> Male | F13: Argentina | G13: Spanish | H13: UI/UX Design | I13: 15 | K13: 2.5125695 | L13: TRUE | M13: 0.86 | N13: Urgent | O13: Active | P13: 13 | Q13: 4 | R13: =IF('global_freelancer-quick ana'!$Q13 < 7, "Short Duration", IF('global_freelancer-quick ana'!$Q13 <= 12, "Medium Duration", "Long Duration")) -> Short Duration | S13: =IF('global_freelancer-quick ana'!$M13 <= 50%, "POOR", IF('global_freelancer-quick ana'!$M13 <= 70%, "GOOD", "EXCELLENT")) -> EXCELLENT | T13: =SUM(B13:S13) -> 90.37257
A14: FL250013 | B14: Alice Schneider | C14: Female | D14: 57 | E14: {=INDEX('global_freelancer-quick ana'!$C$2:$C$1001, MODE(MATCH('global_freelancer-quick ana'!$C$2:$C$1001, 'global_freelancer-quick ana'!$C$2:$C$1001, 0)))} -> Male | F14: UK | G14: English | H14: Cybersecurity | I14: 18 | K14: 2 | L14: FALSE | M14: 0.86 | N14: Reviewed | O14: On Hold | P14: 16 | Q14: 15 | R14: =IF('global_freelancer-quick ana'!$Q14 < 7, "Short Duration", IF('global_freelancer-quick ana'!$Q14 <= 12, "Medium Duration", "Long Duration")) -> Long Duration | S14: =IF('global_freelancer-quick ana'!$M14 <= 50%, "POOR", IF('global_freelancer-quick ana'!$M14 <= 70%, "GOOD", "EXCELLENT")) -> EXCELLENT | T14: =SUM(B14:S14) -> 108.86
A15: FL250014 | B15: Phillip Shelton | C15: Male | D15: 38 | E15: {=INDEX('global_freelancer-quick ana'!$C$2:$C$1001, MODE(MATCH('global_freelancer-quick ana'!$C$2:$C$1001, 'global_freelancer-quick ana'!$C$2:$C$1001, 0)))} -> Male | G15: Spanish | H15: Graphic Design | I15: 20 | J15: 75 | K15: 2.9 | L15: TRUE | M15: 0.93 | N15: Pending | O15: On Hold | P15: 17 | Q15: 12 | R15: =IF('global_freelancer-quick ana'!$Q15 < 7, "Short Duration", IF('global_freelancer-quick ana'!$Q15 <= 12, "Medium Duration", "Long Duration")) -> Medium Duration | S15: =IF('global_freelancer-quick ana'!$M15 <= 50%, "POOR", IF('global_freelancer-quick ana'!$M15 <= 70%, "GOOD", "EXCELLENT")) -> EXCELLENT | T15: =SUM(B15:S15) -> 165.83
A16: FL250015 | B16: Edward Ferguson | C16: Male | D16: 50 | E16: {=INDEX('global_freelancer-quick ana'!$C$2:$C$1001, MODE(MATCH('global_freelancer-quick ana'!$C$2:$C$1001, 'global_freelancer-quick ana'!$C$2:$C$1001, 0)))} -> Male | F16: Germany | G16: Germany | H16: Data Analysis | I16: 22 | J16: 75 | K16: 3.7 | L16: TRUE | M16: 0.7 | N16: Follow-up | O16: Completed | P16: 14 | Q16: 6 | R16: =IF('global_freelancer-quick ana'!$Q16 < 7, "Short Duration", IF('global_freelancer-quick ana'!$Q16 <= 12, "Medium Duration", "Long Duration")) -> Short Duration | S16: =IF('global_freelancer-quick ana'!$M16 <= 50%, "POOR", IF('global_freelancer-quick ana'!$M16 <= 70%, "GOOD", "EXCELLENT")) -> GOOD | T16: =SUM(B16:S16) -> 96.4
A17: FL250016 | B17: Wyatt Stout | C17: Male | D17: 42 | E17: {=INDEX('global_freelancer-quick ana'!$C$2:$C$1001, MODE(MATCH('global_freelancer-quick ana'!$C$2:$C$1001, 'global_freelancer-quick ana'!$C$2:$C$1001, 0)))} -> Male | F17: Japan | G17: Japanese | I17: 0 | J17: 30 | K17: 1.2 | L17: FALSE | M17: 0.69 | N17: Urgent | O17: Active | P17: 5 | Q17: 2 | R17: =IF('global_freelancer-quick ana'!$Q17 < 7, "Short Duration", IF('global_freelancer-quick ana'!$Q17 <= 12, "Medium Duration", "Long Duration")) -> Short Duration | S17: =IF('global_freelancer-quick ana'!$M17 <= 50%, "POOR", IF('global_freelancer-quick ana'!$M17 <= 70%, "GOOD", "EXCELLENT")) -> GOOD | T17: =SUM(B17:S17) -> 80.89
A18: FL250017 | B18: Laura Johnson | C18: Female | D18: 39 | E18: {=INDEX('global_freelancer-quick ana'!$C$2:$C$1001, MODE(MATCH('global_freelancer-quick ana'!$C$2:$C$1001, 'global_freelancer-quick ana'!$C$2:$C$1001, 0)))} -> Male | F18: Australia | G18: English | H18: DevOps | I18: 13 | J18: 30 | K18: 2.5 | L18: FALSE | M18: 0.6 | N18: Follow-up | O18: Inactive | P18: 7 | Q18: 1 | R18: =IF('global_freelancer-quick ana'!$Q18 < 7, "Short Duration", IF('global_freelancer-quick ana'!$Q18 <= 12, "Medium Duration", "Long Duration")) -> Short Duration | S18: =IF('global_freelancer-quick ana'!$M18 <= 50%, "POOR", IF('global_freelancer-quick ana'!$M18 <= 70%, "GOOD", "EXCELLENT")) -> GOOD | T18: =SUM(B18:S18) -> 93.1
A19: FL250018 | B19: Scott Burns | C19: Male | D19: 56 | E19: {=INDEX('global_freelancer-quick ana'!$C$2:$C$1001, MODE(MATCH('global_freelancer-quick ana'!$C$2:$C$1001, 'global_freelancer-quick ana'!$C$2:$C$1001, 0)))} -> Male | F19: India | G19: Hindi | H19: Blockchain Development | I19: 0 | K19: 2.5125695 | L19: Unknown | M19: 0.87 | N19: Pending | O19: Completed | P19: 1 | Q19: 2 | R19: =IF('global_freelancer-quick ana'!$Q19 < 7, "Short Duration", IF('global_freelancer-quick ana'!$Q19 <= 12, "Medium Duration", "Long Duration")) -> Short Duration | S19: =IF('global_freelancer-quick ana'!$M19 <= 50%, "POOR", IF('global_freelancer-quick ana'!$M19 <= 70%, "GOOD", "EXCELLENT")) -> EXCELLENT | T19: =SUM(B19:S19) -> 62.38257
A20: FL250019 | B20: Tyler Aguirre | C20: Male | D20: 56 | E20: {=INDEX('global_freelancer-quick ana'!$C$2:$C$1001, MODE(MATCH('global_freelancer-quick ana'!$C$2:$C$1001, 'global_freelancer-quick ana'!$C$2:$C$1001, 0)))} -> Male | F20: US | G20: English | H20: UI/UX Design | I20: 31 | J20: 50 | K20: 1.1 | L20: FALSE | M20: 0.75 | N20: Urgent | O20: Completed | P20: 13 | Q20: 3 | R20: =IF('global_freelancer-quick ana'!$Q20 < 7, "Short Duration", IF('global_freelancer-quick ana'!$Q20 <= 12, "Medium Duration", "Long Duration")) -> Short Duration | S20: =IF('global_freelancer-quick ana'!$M20 <= 50%, "POOR", IF('global_freelancer-quick ana'!$M20 <= 70%, "GOOD", "EXCELLENT")) -> EXCELLENT | T20: =SUM(B20:S20) -> 154.85
A21: FL250020 | B21: Matthew Lawson | C21: Male | D21: 57 | E21: {=INDEX('global_freelancer-quick ana'!$C$2:$C$1001, MODE(MATCH('global_freelancer-quick ana'!$C$2:$C$1001, 'global_freelancer-quick ana'!$C$2:$C$1001, 0)))} -> Male | F21: Italy | G21: Italian | H21: Web Development | I21: 3 | J21: 100 | K21: 1.8 | L21: TRUE | M21: 0.68 | N21: Follow-up | O21: Completed | P21: 1 | Q21: 1 | R21: =IF('global_freelancer-quick ana'!$Q21 < 7, "Short Duration", IF('global_freelancer-quick ana'!$Q21 <= 12, "Medium Duration", "Long Duration")) -> Short Duration | S21: =IF('global_freelancer-quick ana'!$M21 <= 50%, "POOR", IF('global_freelancer-quick ana'!$M21 <= 70%, "GOOD", "EXCELLENT")) -> GOOD | T21: =SUM(B21:S21) -> 164.48
A22: FL250021 | B22: James Cherry | C22: Male | E22: {=INDEX('global_freelancer-quick ana'!$C$2:$C$1001, MODE(MATCH('global_freelancer-quick ana'!$C$2:$C$1001, 'global_freelancer-quick ana'!$C$2:$C$1001, 0)))} -> Male | F22: Indonesia | G22: Indonesian | H22: AI | I22: 9 | J22: 50 | K22: 1.8 | L22: FALSE | M22: 0.65 | N22: Reviewed | O22: Inactive | P22: 15 | Q22: 6 | R22: =IF('global_freelancer-quick ana'!$Q22 < 7, "Short Duration", IF('global_freelancer-quick ana'!$Q22 <= 12, "Medium Duration", "Long Duration")) -> Short Duration | S22: =IF('global_freelancer-quick ana'!$M22 <= 50%, "POOR", IF('global_freelancer-quick ana'!$M22 <= 70%, "GOOD", "EXCELLENT")) -> GOOD | T22: =SUM(B22:S22) -> 32.45
A23: FL250022 | B23: Samuel Sanford | C23: Male | D23: 51 | E23: {=INDEX('global_freelancer-quick ana'!$C$2:$C$1001, MODE(MATCH('global_freelancer-quick ana'!$C$2:$C$1001, 'global_freelancer-quick ana'!$C$2:$C$1001, 0)))} -> Male | F23: Japan | G23: Japanese | H23: DevOps | I23: 0 | K23: 2.4 | L23: FALSE | M23: 0.69 | N23: Urgent | O23: Completed | P23: 3 | Q23: 5 | R23: =IF('global_freelancer-quick ana'!$Q23 < 7, "Short Duration", IF('global_freelancer-quick ana'!$Q23 <= 12, "Medium Duration", "Long Duration")) -> Short Duration | S23: =IF('global_freelancer-quick ana'!$M23 <= 50%, "POOR", IF('global_freelancer-quick ana'!$M23 <= 70%, "GOOD", "EXCELLENT")) -> GOOD | T23: =SUM(B23:S23) -> 62.09
A24: FL250023 | B24: Cesar Greene | C24: Male | D24: 51 | E24: {=INDEX('global_freelancer-quick ana'!$C$2:$C$1001, MODE(MATCH('global_freelancer-quick ana'!$C$2:$C$1001, 'global_freelancer-quick ana'!$C$2:$C$1001, 0)))} -> Male | F24: Brazil | G24: Portuguese | H24: Cybersecurity | I24: 21 | J24: 30 | K24: 4.7 | L24: FALSE | M24: 0.79 | N24: Follow-up | O24: Inactive | P24: 14 | Q24: 2 | R24: =IF('global_freelancer-quick ana'!$Q24 < 7, "Short Duration", IF('global_freelancer-quick ana'!$Q24 <= 12, "Medium Duration", "Long Duration")) -> Short Duration | S24: =IF('global_freelancer-quick ana'!$M24 <= 50%, "POOR", IF('global_freelancer-quick ana'!$M24 <= 70%, "GOOD", "EXCELLENT")) -> EXCELLENT | T24: =SUM(B24:S24) -> 123.49
A25: FL250024 | B25: Melanie Carter | C25: Female | D25: 51 | E25: {=INDEX('global_freelancer-quick ana'!$C$2:$C$1001, MODE(MATCH('global_freelancer-quick ana'!$C$2:$C$1001, 'global_freelancer-quick ana'!$C$2:$C$1001, 0)))} -> Male | F25: South Korea | G25: Korean | H25: Machine Learning | I25: 15 | J25: 50 | K25: 1.3 | L25: TRUE | M25: 1 | N25: Pending | O25: Completed | P25: 9 | Q25: 3 | R25: =IF('global_freelancer-quick ana'!$Q25 < 7, "Short Duration", IF('global_freelancer-quick ana'!$Q25 <= 12, "Medium Duration", "Long Duration")) -> Short Duration | S25: =IF('global_freelancer-quick ana'!$M25 <= 50%, "POOR", IF('global_freelancer-quick ana'!$M25 <= 70%, "GOOD", "EXCELLENT")) -> EXCELLENT | T25: =SUM(B25:S25) -> 130.3
A26: FL250025 | B26: Jennifer Martin | C26: Female | D26: 54 | E26: {=INDEX('global_freelancer-quick ana'!$C$2:$C$1001, MODE(MATCH('global_freelancer-quick ana'!$C$2:$C$1001, 'global_freelancer-quick ana'!$C$2:$C$1001, 0)))} -> Male | F26: Indonesia | G26: Indonesian | H26: Machine Learning | I26: 13 | J26: 75 | K26: 2.9 | L26: Unknown | M26: 0.92 | N26: Pending | O26: Inactive | P26: 15 | Q26: 3 | R26: =IF('global_freelancer-quick ana'!$Q26 < 7, "Short Duration", IF('global_freelancer-quick ana'!$Q26 <= 12, "Medium Duration", "Long Duration")) -> Short Duration | S26: =IF('global_freelancer-quick ana'!$M26 <= 50%, "POOR", IF('global_freelancer-quick ana'!$M26 <= 70%, "GOOD", "EXCELLENT")) -> EXCELLENT | T26: =SUM(B26:S26) -> 88.82
A27: FL250026 | B27: Anna Mccann | C27: Female | D27: 22 | E27: {=INDEX('global_freelancer-quick ana'!$C$2:$C$1001, MODE(MATCH('global_freelancer-quick ana'!$C$2:$C$1001, 'global_freelancer-quick ana'!$C$2:$C$1001, 0)))} -> Male | F27: South Korea | G27: Korean | H27: DevOps | I27: 0 | J27: 30 | K27: 1.2 | L27: TRUE | M27: 0.7 | N27: Urgent | O27: On Hold | P27: 5 | Q27: 2 | R27: =IF('global_freelancer-quick ana'!$Q27 < 7, "Short Duration", IF('global_freelancer-quick ana'!$Q27 <= 12, "Medium Duration", "Long Duration")) -> Short Duration | S27: =IF('global_freelancer-quick ana'!$M27 <= 50%, "POOR", IF('global_freelancer-quick ana'!$M27 <= 70%, "GOOD", "EXCELLENT")) -> GOOD | T27: =SUM(B27:S27) -> 60.9
A28: FL250027 | B28: Marissa Bass | C28: Female | D28: 34 | E28: {=INDEX('global_freelancer-quick ana'!$C$2:$C$1001, MODE(MATCH('global_freelancer-quick ana'!$C$2:$C$1001, 'global_freelancer-quick ana'!$C$2:$C$1001, 0)))} -> Male | F28: Japan | G28: Japanese | H28: Blockchain Development | I28: 8 | J28: 20 | K28: 0 | L28: TRUE | M28: 0.89 | N28: Follow-up | O28: On Hold | P28: 6 | Q28: 1 | R28: =IF('global_freelancer-quick ana'!$Q28 < 7, "Short Duration", IF('global_freelancer-quick ana'!$Q28 <= 12, "Medium Duration", "Long Duration")) -> Short Duration | S28: =IF('global_freelancer-quick ana'!$M28 <= 50%, "POOR", IF('global_freelancer-quick ana'!$M28 <= 70%, "GOOD", "EXCELLENT")) -> EXCELLENT | T28: =SUM(B28:S28) -> 69.89
A29: FL250028 | B29: Alexis Day | C29: Female | D29: 36 | E29: {=INDEX('global_freelancer-quick ana'!$C$2:$C$1001, MODE(MATCH('global_freelancer-quick ana'!$C$2:$C$1001, 'global_freelancer-quick ana'!$C$2:$C$1001, 0)))} -> Male | F29: Russia | G29: Russian | H29: Graphic Design | I29: 11 | K29: 1.8 | L29: TRUE | M29: 0.86 | N29: Urgent | O29: On Hold | P29: 12 | Q29: 4 | R29: =IF('global_freelancer-quick ana'!$Q29 < 7, "Short Duration", IF('global_freelancer-quick ana'!$Q29 <= 12, "Medium Duration", "Long Duration")) -> Short Duration | S29: =IF('global_freelancer-quick ana'!$M29 <= 50%, "POOR", IF('global_freelancer-quick ana'!$M29 <= 70%, "GOOD", "EXCELLENT")) -> EXCELLENT | T29: =SUM(B29:S29) -> 65.66
A30: FL250029 | B30: Megan Jones | C30: Female | D30: 47 | E30: {=INDEX('global_freelancer-quick ana'!$C$2:$C$1001, MODE(MATCH('global_freelancer-quick ana'!$C$2:$C$1001, 'global_freelancer-quick ana'!$C$2:$C$1001, 0)))} -> Male | F30: Canada | G30: English | H30: AI | I30: 22 | J30: 30 | K30: 1.3 | L30: FALSE | M30: 0.62 | N30: Urgent | O30: On Hold | P30: 14 | Q30: 2 | R30: =IF('global_freelancer-quick ana'!$Q30 < 7, "Short Duration", IF('global_freelancer-quick ana'!$Q30 <= 12, "Medium Duration", "Long Duration")) -> Short Duration | S30: =IF('global_freelancer-quick ana'!$M30 <= 50%, "POOR", IF('global_freelancer-quick ana'!$M30 <= 70%, "GOOD", "EXCELLENT")) -> GOOD | T30: =SUM(B30:S30) -> 86.92
A31: FL250030 | B31: Lori Smith | C31: Female | D31: 41 | E31: {=INDEX('global_freelancer-quick ana'!$C$2:$C$1001, MODE(MATCH('global_freelancer-quick ana'!$C$2:$C$1001, 'global_freelancer-quick ana'!$C$2:$C$1001, 0)))} -> Male | F31: Netherlands | G31: Dutch | H31: Data Analysis | I31: 14 | J31: 75 | K31: 1.2 | L31: FALSE | M31: 0.79 | N31: Follow-up | O31: On Hold | P31: 6 | Q31: 5 | R31: =IF('global_freelancer-quick ana'!$Q31 < 7, "Short Duration", IF('global_freelancer-quick ana'!$Q31 <= 12, "Medium Duration", "Long Duration")) -> Short Duration | S31: =IF('global_freelancer-quick ana'!$M31 <= 50%, "POOR", IF('global_freelancer-quick ana'!$M31 <= 70%, "GOOD", "EXCELLENT")) -> EXCELLENT | T31: =SUM(B31:S31) -> 142.99
A32: FL250031 | B32: Eric Carpenter | C32: Male | D32: 22 | E32: {=INDEX('global_freelancer-quick ana'!$C$2:$C$1001, MODE(MATCH('global_freelancer-quick ana'!$C$2:$C$1001, 'global_freelancer-quick ana'!$C$2:$C$1001, 0)))} -> Male | F32: Netherlands | G32: Dutch | H32: DevOps | I32: 4 | K32: 1 | L32: TRUE | M32: 0.79 | N32: Follow-up | O32: Completed | P32: 3 | Q32: 1 | R32: =IF('global_freelancer-quick ana'!$Q32 < 7, "Short Duration", IF('global_freelancer-quick ana'!$Q32 <= 12, "Medium Duration", "Long Duration")) -> Short Duration | S32: =IF('global_freelancer-quick ana'!$M32 <= 50%, "POOR", IF('global_freelancer-quick ana'!$M32 <= 70%, "GOOD", "EXCELLENT")) -> EXCELLENT | T32: =SUM(B32:S32) -> 31.79
A33: FL250032 | B33: Timothy Daniels | C33: Male | D33: 38 | E33: {=INDEX('global_freelancer-quick ana'!$C$2:$C$1001, MODE(MATCH('global_freelancer-quick ana'!$C$2:$C$1001, 'global_freelancer-quick ana'!$C$2:$C$1001, 0)))} -> Male | F33: France | G33: French | H33: Machine Learning | I33: 19 | J33: 100 | K33: 4.2 | L33: FALSE | M33: 0.68 | N33: Reviewed | O33: Completed | P33: 10 | Q33: 10 | R33: =IF('global_freelancer-quick ana'!$Q33 < 7, "Short Duration", IF('global_freelancer-quick ana'!$Q33 <= 12, "Medium Duration", "Long Duration")) -> Medium Duration | S33: =IF('global_freelancer-quick ana'!$M33 <= 50%, "POOR", IF('global_freelancer-quick ana'!$M33 <= 70%, "GOOD", "EXCELLENT")) -> GOOD | T33: =SUM(B33:S33) -> 181.88
A34: FL250033 | B34: Robert Nelson | C34: Male | D34: 46 | E34: {=INDEX('global_freelancer-quick ana'!$C$2:$C$1001, MODE(MATCH('global_freelancer-quick ana'!$C$2:$C$1001, 'global_freelancer-quick ana'!$C$2:$C$1001, 0)))} -> Male | F34: Egypt | G34: Arabic | H34: AI | I34: 9 | J34: 20 | K34: 1.4 | L34: TRUE | M34: 0.76 | N34: Follow-up | O34: Completed | P34: 13 | Q34: 6 | R34: =IF('global_freelancer-quick ana'!$Q34 < 7, "Short Duration", IF('global_freelancer-quick ana'!$Q34 <= 12, "Medium Duration", "Long Duration")) -> Short Duration | S34: =IF('global_freelancer-quick ana'!$M34 <= 50%, "POOR", IF('global_freelancer-quick ana'!$M34 <= 70%, "GOOD", "EXCELLENT")) -> EXCELLENT | T34: =SUM(B34:S34) -> 76.16
A35: FL250034 | B35: Michael Anderson | C35: Male | E35: {=INDEX('global_freelancer-quick ana'!$C$2:$C$1001, MODE(MATCH('global_freelancer-quick ana'!$C$2:$C$1001, 'global_freelancer-quick ana'!$C$2:$C$1001, 0)))} -> Male | F35: South Korea | G35: Korean | H35: AI | I35: 9 | J35: 40 | K35: 2.4 | L35: TRUE | M35: 0.82 | N35: Pending | O35: Inactive | P35: 15 | Q35: 3 | R35: =IF('global_freelancer-quick ana'!$Q35 < 7, "Short Duration", IF('global_freelancer-quick ana'!$Q35 <= 12, "Medium Duration", "Long Duration")) -> Short Duration | S35: =IF('global_freelancer-quick ana'!$M35 <= 50%, "POOR", IF('global_freelancer-quick ana'!$M35 <= 70%, "GOOD", "EXCELLENT")) -> EXCELLENT | T35: =SUM(B35:S35) -> 30.22
A36: FL250035 | B36: Jessica Snyder | C36: Female | D36: 54 | E36: {=INDEX('global_freelancer-quick ana'!$C$2:$C$1001, MODE(MATCH('global_freelancer-quick ana'!$C$2:$C$1001, 'global_freelancer-quick ana'!$C$2:$C$1001, 0)))} -> Male | F36: US | G36: English | H36: Web Development | I36: 32 | J36: 75 | K36: 1 | L36: TRUE | M36: 0.81 | N36: Urgent | O36: Inactive | P36: 18 | Q36: 10 | R36: =IF('global_freelancer-quick ana'!$Q36 < 7, "Short Duration", IF('global_freelancer-quick ana'!$Q36 <= 12, "Medium Duration", "Long Duration")) -> Medium Duration | S36: =IF('global_freelancer-quick ana'!$M36 <= 50%, "POOR", IF('global_freelancer-quick ana'!$M36 <= 70%, "GOOD", "EXCELLENT")) -> EXCELLENT | T36: =SUM(B36:S36) -> 115.81
A37: FL250036 | B37: Emily Daniels | C37: Female | D37: 52 | E37: {=INDEX('global_freelancer-quick ana'!$C$2:$C$1001, MODE(MATCH('global_freelancer-quick ana'!$C$2:$C$1001, 'global_freelancer-quick ana'!$C$2:$C$1001, 0)))} -> Male | F37: South Korea | G37: Korean | I37: 28 | J37: 20 | K37: 2.5125695 | L37: FALSE | M37: 0.79 | N37: Urgent | O37: Inactive | P37: 18 | Q37: 2 | R37: =IF('global_freelancer-quick ana'!$Q37 < 7, "Short Duration", IF('global_freelancer-quick ana'!$Q37 <= 12, "Medium Duration", "Long Duration")) -> Short Duration | S37: =IF('global_freelancer-quick ana'!$M37 <= 50%, "POOR", IF('global_freelancer-quick ana'!$M37 <= 70%, "GOOD", "EXCELLENT")) -> EXCELLENT | T37: =SUM(B37:S37) -> 123.30257
A38: FL250037 | B38: Jamie Ramirez | C38: Female | D38: 42 | E38: {=INDEX('global_freelancer-quick ana'!$C$2:$C$1001, MODE(MATCH('global_freelancer-quick ana'!$C$2:$C$1001, 'global_freelancer-quick ana'!$C$2:$C$1001, 0)))} -> Male | F38: Japan | G38: Japanese | H38: Mobile Apps | I38: 6 | J38: 40 | K38: 2.5125695 | L38: FALSE | M38: 0.63 | N38: Pending | O38: Inactive | P38: 15 | Q38: 6 | R38: =IF('global_freelancer-quick ana'!$Q38 < 7, "Short Duration", IF('global_freelancer-quick ana'!$Q38 <= 12, "Medium Duration", "Long Duration")) -> Short Duration | S38: =IF('global_freelancer-quick ana'!$M38 <= 50%, "POOR", IF('global_freelancer-quick ana'!$M38 <= 70%, "GOOD", "EXCELLENT")) -> GOOD | T38: =SUM(B38:S38) -> 72.14257
A39: FL250038 | B39: Amy Harrison | C39: Female | D39: 29 | E39: {=INDEX('global_freelancer-quick ana'!$C$2:$C$1001, MODE(MATCH('global_freelancer-quick ana'!$C$2:$C$1001, 'global_freelancer-quick ana'!$C$2:$C$1001, 0)))} -> Male | F39: Netherlands | G39: Dutch | H39: Graphic Design | I39: 10 | J39: 40 | K39: 2.2 | L39: FALSE | M39: 0.67 | N39: Follow-up | O39: On Hold | P39: 10 | Q39: 9 | R39: =IF('global_freelancer-quick ana'!$Q39 < 7, "Short Duration", IF('global_freelancer-quick ana'!$Q39 <= 12, "Medium Duration", "Long Duration")) -> Medium Duration | S39: =IF('global_freelancer-quick ana'!$M39 <= 50%, "POOR", IF('global_freelancer-quick ana'!$M39 <= 70%, "GOOD", "EXCELLENT")) -> GOOD | T39: =SUM(B39:S39) -> 60.87
A40: FL250039 | B40: Melinda White | C40: Female | D40: 42 | E40: {=INDEX('global_freelancer-quick ana'!$C$2:$C$1001, MODE(MATCH('global_freelancer-quick ana'!$C$2:$C$1001, 'global_freelancer-quick ana'!$C$2:$C$1001, 0)))} -> Male | F40: South Africa | G40: Afrikaans | H40: Mobile Apps | I40: 23 | J40: 50 | K40: 3.2 | L40: TRUE | M40: 0.79 | N40: Pending | O40: On Hold | P40: 13 | Q40: 3 | R40: =IF('global_freelancer-quick ana'!$Q40 < 7, "Short Duration", IF('global_freelancer-quick ana'!$Q40 <= 12, "Medium Duration", "Long Duration")) -> Short Duration | S40: =IF('global_freelancer-quick ana'!$M40 <= 50%, "POOR", IF('global_freelancer-quick ana'!$M40 <= 70%, "GOOD", "EXCELLENT")) -> EXCELLENT | T40: =SUM(B40:S40) -> 84.99
...

Sheet Formula
A2: checking Duration period
A3: IF([@[duration_months]] < 7, "Short Duration", IF([@[duration_months]] <= 12, "Medium Duration", "Long Duration"))
A5: IF([@[client_satisfaction]] <= 50%, "POOR", IF([@[client_satisfaction]] <= 70%, "GOOD", "EXCELLENT"))
A7: Date & Time Functions
A8: TODAY(), NOW(), YEAR(), MONTH(), WEEKDAY(), DATEDIF()
A10: =TODAY() -> 45987 | E10: TODAY()
A11: =NOW() -> 45987.506 | E11: NOW()
A12: =YEAR(A10) -> 2025 | E12: YEAR(A10)
A13: =MONTH(A10) -> 11 | E13: MONTH(A10)
A14: Calculating age
A15: 34783 | C15: =DATEDIF(A15, TODAY(), "Y") -> 30 | E15: DATEDIF(A15, TODAY(), "Y")
A19: VLOOKUP
A21: ID | B21: NAME | C21: RATING
A22: FL250001 | B22: Ms. Nicole Kidd | C22: 2.5125695
A23: FL250002 | B23: Vanessa Garcia | C23: 3.3
A24: FL250003 | B24: Juan Nelson | C24: 0
A25: FL250004 | B25: Amanda Spencer | C25: 1.5
A26: FL250005 | B26: Lynn Curtis DDS | C26: 4.8
A27: FL250006 | B27: Lisa Johnson | C27: 2.4
A28: FL250007 | B28: Eric Myers | C28: 3.1
A29: FL250008 | B29: Ricky Graham | C29: 4.6
A30: FL250009 | B30: Sean Martin | C30: 4
A32: XLOOKUP
A33: id | B33: NAME | C33: Rating
A34: FL250006 | B34: Ricky Graham | C34: {=_xlfn.XLOOKUP(A34&B34,A22:A30&B22:B30,C22:C30, 1)} -> 1 | E34: XLOOKUP(A34&B34,A22:A30&B22:B30,C22:C30, 1)
A36: VLOOKUP
B37: ID | C37: RATING
B38: FL250008 | C38: =VLOOKUP(B38,A21:C30, 3, FALSE) -> 4.6 | E38: VLOOKUP(B38,A21:C30, 3, FALSE)
A41: INDEX AND MATCH FORMULA
A43: INDEX(global_freelancer_raw!$C$2:$C$1001, MODE(MATCH(global_freelancer_raw!$C$2:$C$1001, global_freelancer_raw!$C$2:$C$1001, 0)))

Sheet Power Query
A1: freelancer_ID | B1: name | C1: gender | D1: age | E1: country | F1: language | G1: primary_skill | H1: years_of_experience | I1: hourly_rate (USD) | J1: rating | K1: is_active | L1: client_satisfaction | M1: Notes | N1: Status | O1: no of projects | P1: duration_months | Q1: Duration Period | R1: Client satisfaction analysis | S1: Column1
A2: FL250001 | B2: Ms. Nicole Kidd | C2: Female | D2: 52 | E2: Italy | F2: Italian | G2: Blockchain Development | H2: 11 | I2: 100 | J2: 2.5125695 | K2: FALSE | L2: 0.79 | M2: Reviewed | N2: On Hold | O2: 13 | P2: 6 | Q2: Short Duration | R2: EXCELLENT | S2: =SUM(D2:R2) -> 185.30257
A3: FL250002 | B3: Vanessa Garcia | C3: Female | D3: 52 | E3: Australia | F3: English | G3: Mobile Apps | H3: 34 | I3: 100 | J3: 3.3 | K3: TRUE | L3: 0.84 | M3: Reviewed | N3: Completed | O3: 10 | P3: 7 | Q3: Medium Duration | R3: EXCELLENT | S3: =SUM(D3:R3) -> 207.14
A4: FL250003 | B4: Juan Nelson | C4: Male | D4: 53 | E4: Germany | F4: Germany | G4: Graphic Design | H4: 31 | I4: 50 | J4: 0 | K4: FALSE | L4: 0.71 | M4: Reviewed | N4: Active | O4: 16 | P4: 16 | Q4: Long Duration | R4: EXCELLENT | S4: =SUM(D4:R4) -> 166.71
A5: FL250004 | B5: Amanda Spencer | C5: Female | D5: 38 | E5: Australia | F5: English | G5: Web Development | H5: 4 | I5: 40 | J5: 1.5 | K5: FALSE | L5: 0.9 | M5: Reviewed | N5: Completed | O5: 5 | P5: 1 | Q5: Short Duration | R5: EXCELLENT | S5: =SUM(D5:R5) -> 90.4
A6: FL250005 | B6: Lynn Curtis DDS | C6: Female | D6: 53 | E6: Germany | F6: Germany | H6: 27 | I6: 30 | J6: 4.8 | K6: FALSE | L6: 0.83 | M6: Reviewed | N6: On Hold | O6: 13 | P6: 3 | Q6: Short Duration | R6: EXCELLENT | S6: =SUM(D6:R6) -> 131.63
A7: FL250006 | B7: Lisa Johnson | C7: Female | D7: 59 | E7: Netherlands | F7: Dutch | G7: AI | H7: 14 | I7: 30 | J7: 2.4 | K7: FALSE | L7: 0.79 | M7: Urgent | N7: Active | O7: 8 | P7: 3 | Q7: Short Duration | R7: EXCELLENT | S7: =SUM(D7:R7) -> 117.19
A8: FL250007 | B8: Eric Myers | C8: Male | D8: 52 | E8: Indonesia | F8: Indonesian | G8: Data Analysis | H8: 10 | I8: 75 | J8: 3.1 | K8: FALSE | L8: 0.94 | M8: Reviewed | N8: On Hold | O8: 10 | P8: 3 | Q8: Short Duration | R8: EXCELLENT | S8: =SUM(D8:R8) -> 154.04
A9: FL250008 | B9: Ricky Graham | C9: Male | D9: 43 | E9: Italy | F9: Italian | G9: Blockchain Development | H9: 14 | I9: 40 | J9: 4.6 | K9: FALSE | L9: 0.94 | M9: Urgent | N9: On Hold | O9: 7 | P9: 10 | Q9: Medium Duration | R9: EXCELLENT | S9: =SUM(D9:R9) -> 119.54
A10: FL250009 | B10: Sean Martin | C10: Male | D10: 26 | E10: US | F10: English | G10: Blockchain Development | H10: 4 | J10: 4 | K10: TRUE | L10: 0.76 | M10: Reviewed | N10: Inactive | O10: 2 | P10: 4 | Q10: Short Duration | R10: EXCELLENT | S10: =SUM(D10:R10) -> 40.76
A11: FL250010 | B11: Matthew Lloyd | C11: Male | D11: 52 | E11: Turkey | F11: Turkish | G11: AI | H11: 22 | I11: 50 | J11: 2.5125695 | K11: TRUE | L11: 0.79 | M11: Pending | N11: Active | O11: 16 | P11: 5 | Q11: Short Duration | R11: EXCELLENT | S11: =SUM(D11:R11) -> 148.30257
A12: FL250011 | B12: Gavin Randall | C12: Male | D12: 40 | E12: UK | F12: English | G12: Data Analysis | H12: 17 | I12: 40 | J12: 3.6 | K12: TRUE | L12: 0.77 | M12: Follow-up | N12: Inactive | O12: 20 | P12: 5 | Q12: Short Duration | R12: EXCELLENT | S12: =SUM(D12:R12) -> 126.37
A13: FL250012 | B13: Michelle Curtis | C13: Female | D13: 55 | E13: Argentina | F13: Spanish | G13: UI/UX Design | H13: 15 | J13: 2.5125695 | K13: TRUE | L13: 0.86 | M13: Urgent | N13: Active | O13: 13 | P13: 4 | Q13: Short Duration | R13: EXCELLENT | S13: =SUM(D13:R13) -> 90.37257
A14: FL250013 | B14: Alice Schneider | C14: Female | D14: 57 | E14: UK | F14: English | G14: Cybersecurity | H14: 18 | J14: 2 | K14: FALSE | L14: 0.86 | M14: Reviewed | N14: On Hold | O14: 16 | P14: 15 | Q14: Long Duration | R14: EXCELLENT | S14: =SUM(D14:R14) -> 108.86
A15: FL250014 | B15: Phillip Shelton | C15: Male | D15: 38 | F15: Spanish | G15: Graphic Design | H15: 20 | I15: 75 | J15: 2.9 | K15: TRUE | L15: 0.93 | M15: Pending | N15: On Hold | O15: 17 | P15: 12 | Q15: Medium Duration | R15: EXCELLENT | S15: =SUM(D15:R15) -> 165.83
A16: FL250015 | B16: Edward Ferguson | C16: Male | D16: 50 | E16: Germany | F16: Germany | G16: Data Analysis | H16: 22 | I16: 75 | J16: 3.7 | K16: TRUE | L16: 0.7 | M16: Follow-up | N16: Completed | O16: 14 | P16: 6 | Q16: Short Duration | R16: GOOD | S16: =SUM(D16:R16) -> 171.4
A17: FL250016 | B17: Wyatt Stout | C17: Male | D17: 42 | E17: Japan | F17: Japanese | H17: 0 | I17: 30 | J17: 1.2 | K17: FALSE | L17: 0.69 | M17: Urgent | N17: Active | O17: 5 | P17: 2 | Q17: Short Duration | R17: GOOD | S17: =SUM(D17:R17) -> 80.89
